{
  "data_type": "CVE",
  "data_format": "MITRE",
  "data_version": "4.0",
  "CVE_data_meta": {
    "ID": "CVE-2021-3116",
    "ASSIGNER": "cve@mitre.org"
  },
  "problemtype": {
    "problemtype_data": [
      {
        "description": [
          {
            "lang": "en",
            "value": "CWE-697"
          }
        ]
      }
    ]
  },
  "references": {
    "reference_data": [
      {
        "url": "https://pypi.org/project/proxy.py/2.3.1/#history",
        "name": "https://pypi.org/project/proxy.py/2.3.1/#history",
        "refsource": "MISC",
        "tags": [
          "Product"
        ]
      },
      {
        "url": "https://cardaci.xyz/advisories/2021/01/10/proxy.py-2.3.0-broken-basic-authentication/",
        "name": "https://cardaci.xyz/advisories/2021/01/10/proxy.py-2.3.0-broken-basic-authentication/",
        "refsource": "MISC",
        "tags": [
          "Exploit",
          "Third Party Advisory"
        ]
      },
      {
        "url": "https://github.com/abhinavsingh/proxy.py/pull/482/commits/9b00093288237f5073c403f2c4f62acfdfa8ed46",
        "name": "https://github.com/abhinavsingh/proxy.py/pull/482/commits/9b00093288237f5073c403f2c4f62acfdfa8ed46",
        "refsource": "MISC",
        "tags": [
          "Patch"
        ]
      }
    ]
  },
  "description": {
    "description_data": [
      {
        "lang": "en",
        "value": "before_upstream_connection in AuthPlugin in http/proxy/auth.py in proxy.py before 2.3.1 accepts incorrect Proxy-Authorization header data because of a boolean confusion (and versus or)."
      }
    ]
  }
}