{
  "data_type": "CVE",
  "data_format": "MITRE",
  "data_version": "4.0",
  "CVE_data_meta": {
    "ID": "CVE-2023-39661",
    "ASSIGNER": "cve@mitre.org"
  },
  "problemtype": {
    "problemtype_data": [
      {
        "description": [
          {
            "lang": "en",
            "value": "CWE-74"
          }
        ]
      }
    ]
  },
  "references": {
    "reference_data": [
      {
        "url": "https://github.com/gventuri/pandas-ai/issues/410",
        "name": "https://github.com/gventuri/pandas-ai/issues/410",
        "refsource": "MISC",
        "tags": [
          "Exploit",
          "Issue Tracking",
          "Third Party Advisory"
        ]
      }
    ]
  },
  "description": {
    "description_data": [
      {
        "lang": "en",
        "value": "An issue in pandas-ai v.0.9.1 and before allows a remote attacker to execute arbitrary code via the _is_jailbreak function."
      }
    ]
  }
}