{
  "data_type": "CVE",
  "data_format": "MITRE",
  "data_version": "4.0",
  "CVE_data_meta": {
    "ID": "CVE-2009-5010",
    "ASSIGNER": "cve@mitre.org"
  },
  "problemtype": {
    "problemtype_data": [
      {
        "description": [
          {
            "lang": "en",
            "value": "CWE-362"
          }
        ]
      }
    ]
  },
  "references": {
    "reference_data": [
      {
        "url": "http://code.google.com/p/pyftpdlib/source/detail?r=439",
        "name": "http://code.google.com/p/pyftpdlib/source/detail?r=439",
        "refsource": "CONFIRM",
        "tags": []
      },
      {
        "url": "https://bugs.launchpad.net/zodb/+bug/135108",
        "name": "https://bugs.launchpad.net/zodb/+bug/135108",
        "refsource": "MISC",
        "tags": []
      },
      {
        "url": "http://www.openwall.com/lists/oss-security/2010/09/24/3",
        "name": "[oss-security] 20100924 Re: CVE Request -- Python -- accept() implementation in async core is broken => more subcases",
        "refsource": "MLIST",
        "tags": []
      },
      {
        "url": "http://code.google.com/p/pyftpdlib/issues/detail?id=91",
        "name": "http://code.google.com/p/pyftpdlib/issues/detail?id=91",
        "refsource": "CONFIRM",
        "tags": []
      },
      {
        "url": "http://code.google.com/p/pyftpdlib/source/diff?spec=svn439&r=439&format=side&path=/trunk/pyftpdlib/ftpserver.py",
        "name": "http://code.google.com/p/pyftpdlib/source/diff?spec=svn439&r=439&format=side&path=/trunk/pyftpdlib/ftpserver.py",
        "refsource": "CONFIRM",
        "tags": []
      },
      {
        "url": "http://bugs.python.org/issue6706",
        "name": "http://bugs.python.org/issue6706",
        "refsource": "MISC",
        "tags": [
          "Patch"
        ]
      },
      {
        "url": "http://code.google.com/p/pyftpdlib/source/browse/trunk/HISTORY",
        "name": "http://code.google.com/p/pyftpdlib/source/browse/trunk/HISTORY",
        "refsource": "CONFIRM",
        "tags": []
      },
      {
        "url": "http://www.openwall.com/lists/oss-security/2010/09/09/6",
        "name": "[oss-security] 20100909 CVE Request -- Python -- accept() implementation in async core is broken => more subcases",
        "refsource": "MLIST",
        "tags": []
      },
      {
        "url": "http://www.openwall.com/lists/oss-security/2010/09/22/3",
        "name": "[oss-security] 20100922 Re: CVE Request -- Python -- accept() implementation in async core is broken => more subcases",
        "refsource": "MLIST",
        "tags": []
      },
      {
        "url": "http://www.openwall.com/lists/oss-security/2010/09/11/2",
        "name": "[oss-security] 20100910 Re: CVE Request -- Python -- accept() implementation in async core is broken => more subcases",
        "refsource": "MLIST",
        "tags": []
      }
    ]
  },
  "description": {
    "description_data": [
      {
        "lang": "en",
        "value": "Race condition in the FTPHandler class in ftpserver.py in pyftpdlib before 0.5.1 allows remote attackers to cause a denial of service (daemon outage) by establishing and then immediately closing a TCP connection, leading to the accept function having an unexpected return value of None, a different vulnerability than CVE-2010-3494."
      }
    ]
  }
}