{
  "data_type": "CVE",
  "data_format": "MITRE",
  "data_version": "4.0",
  "CVE_data_meta": {
    "ID": "CVE-2015-5145",
    "ASSIGNER": "cve@mitre.org"
  },
  "problemtype": {
    "problemtype_data": [
      {
        "description": [
          {
            "lang": "en",
            "value": "CWE-399"
          }
        ]
      }
    ]
  },
  "references": {
    "reference_data": [
      {
        "url": "https://www.djangoproject.com/weblog/2015/jul/08/security-releases/",
        "name": "https://www.djangoproject.com/weblog/2015/jul/08/security-releases/",
        "refsource": "CONFIRM",
        "tags": [
          "Vendor Advisory"
        ]
      },
      {
        "url": "http://www.securityfocus.com/bid/75691",
        "name": "75691",
        "refsource": "BID",
        "tags": []
      },
      {
        "url": "https://security.gentoo.org/glsa/201510-06",
        "name": "GLSA-201510-06",
        "refsource": "GENTOO",
        "tags": []
      },
      {
        "url": "http://www.securitytracker.com/id/1032820",
        "name": "1032820",
        "refsource": "SECTRACK",
        "tags": []
      }
    ]
  },
  "description": {
    "description_data": [
      {
        "lang": "en",
        "value": "validators.URLValidator in Django 1.8.x before 1.8.3 allows remote attackers to cause a denial of service (CPU consumption) via unspecified vectors."
      }
    ]
  }
}